Workbook

Sheet Cover
B2: CONTAINER WORKSHOP — BILL OF MATERIALS
B3: 集装箱车间 — 材料清单 · Request for Quotation 询价书
B5: RFQ number | C5: RFQ-CW-2026-001
B6: Design revision | C6: C — 2026-08-24, status: for engineering
B7: Issued | C7: 2026-09-24
B8: Quotations due | C8: 2026-10-22
B9: Buyer contact | C9: aaron@carbonproject.com.au
B10: Delivery basis | C10: FOB nominated China port; freight to CIF Port of Brisbane, Australia as separate lines
B11: Currency | C11: USD (state exchange assumptions for any CNY components)
B12: Validity required | C12: 90 days from submission
B14: HOW TO COMPLETE THIS WORKBOOK 填写说明
B15: 1. Enter unit rates ONLY in the yellow cells on the BOM sheet (column I) and the freight lines on the Group summary sheet. Amounts and rollups calculate automatically.
B16: 2. Quote every line in your package scope. Leave a yellow cell empty only if the line is excluded — and say so in column K.
B17: 3. Scope codes: CN = base scope, quote required. CN-OPT = priced option, excluded from the base total. LOCAL = Australian local supply or site works — for information only, do not quote.
B18: 4. Record every deviation, substitution or alternative in column K (Tenderer remarks). Substitutions of Australian steel sections (UB/UC to AS/NZS 3679.1) require documented section-property equivalence and are not accepted without written approval.
B19: 5. Nominal masses are for freight planning only; final masses come from your shop detailing. Rate and amount columns arrive empty by design: no prices are invented anywhere in this package — they come from supplier quotes.
B20: 6. Return this workbook in .xlsx format together with the technical submissions listed in the RFQ brief. The English text governs. 如有歧义，以英文版本为准。
B22: LEGEND & EXAMPLE 图例
B23: Yellow cell = tenderer input | C23: Blue text = entered value · Black = calculated · Grey row = LOCAL, not quoted
B25: Example only | C25: Unit | D25: Qty | E25: Unit rate (USD) | F25: Amount (USD)
B26: Purlin Z200-19 (illustration of expected format — not a real price) | C26: m | D26: 100 | E26: 8.5 | F26: =D26*E26 -> 850
B28: This BOM derives from the rev C parametric design package (Fusion master: Container Workshop MASTER). It is coordinated and dimensionally consistent but NOT a certified design: structural, plant-registration and electrical certification happen in Australia against the successful tenderer's shop drawings and data. See the RFQ brief for the 15-item sign-off register, quality requirements, packing and shipping terms.

Sheet BOM
A1: Item | B1: Description | C1: Specification / standard | D1: Notes | E1: Unit | F1: Qty | G1: Nominal mass (kg) | H1: Scope | I1: Unit rate (USD) | J1: Amount (USD) | K1: Tenderer remarks / deviations
A2: A | B2: ISO CONTAINERS & INTER-CONNECTION
A3: A-01 | B3: 40 ft high-cube ISO shipping container, one-trip condition | C3: ISO 668 1AAA, 12.192 x 2.438 x 2.896 m, CSC safety-approval plated, doors and seals intact | D3: The three containers form the building and double as the export freight containers for this kit (shipper-owned containers) | E3: ea | F3: 3 | G3: 11700 | H3: CN | J3: =IF(OR($I3="",$H3="LOCAL"),"",ROUND($F3*$I3,0))
A4: A-02 | B4: Inter-container corner connection plate set, bolted | C4: HDG to AS/NZS 4680; engages ISO corner castings top and bottom | D4: Containers meet at both rear corners of the 12.192 x 12.192 m bay | E4: set | F4: 4 | G4: 120 | H4: CN | J4: =IF(OR($I4="",$H4="LOCAL"),"",ROUND($F4*$I4,0))
A5: A-03 | B5: Container-to-slab hold-down bracket | C5: HDG cleat to suit bottom corner casting, M16 chemical-anchor fixing | D5: 4 per container; anchors in group X | E5: ea | F5: 12 | G5: 96 | H5: CN | J5: =IF(OR($I5="",$H5="LOCAL"),"",ROUND($F5*$I5,0))
A6: A-04 | B6: Container survey, prep and rail inspection report | C6: Top side-rail straightness and corner-casting condition recorded per unit | D6: Top side rails carry the storage-deck bearers — condition is structural | E6: ea | F6: 3 | H6: CN | J6: =IF(OR($I6="",$H6="LOCAL"),"",ROUND($F6*$I6,0))
A7: A-05 | B7: Container repaint system, exterior and cut edges | C7: 2-pack polyurethane over epoxy primer, marine grade; colour advised at order | D7: Applied after modification group B | E7: lot | F7: 1 | H7: CN | J7: =IF(OR($I7="",$H7="LOCAL"),"",ROUND($F7*$I7,0))
A8: B | B8: CONTAINER MODIFICATION & BAY STRUCTURE
A9: B-01 | B9: Side-wall opening, cut and dressed, 2.288 m w x 2.500 m h | C9: Cut lines sealed and primed; corrugation edges dressed | D9: 15 openings = 85.8 m2 of stressed skin removed; structural sign-off by principal's engineer before fabrication | E9: ea | F9: 15 | H9: CN | J9: =IF(OR($I9="",$H9="LOCAL"),"",ROUND($F9*$I9,0))
A10: B-02 | B10: Goalpost reinforcement frame at opening (2 posts + head) | C10: 150 PFC G300, welded frame, HDG; weld to AS/NZS 1554.1 SP | D10: One frame per opening restores racking stiffness lost with the skin | E10: set | F10: 15 | G10: 2100 | H10: CN | J10: =IF(OR($I10="",$H10="LOCAL"),"",ROUND($F10*$I10,0))
A11: B-03 | B11: Opening perimeter trim / jamb-head flashing set | C11: 1.2 BMT folded galv steel, colour-matched | E11: set | F11: 15 | G11: 150 | H11: CN | J11: =IF(OR($I11="",$H11="LOCAL"),"",ROUND($F11*$I11,0))
A12: B-04 | B12: Head deflection plate and packer set | C12: 10 mm plate + slotted packers | D12: Isolates goalpost head from container top-rail deflection | E12: set | F12: 15 | G12: 90 | H12: CN | J12: =IF(OR($I12="",$H12="LOCAL"),"",ROUND($F12*$I12,0))
A13: B-05 | B13: Server compartment fit-out: sealed insulated lining + access door | C13: Stud-framed lining, 50 mm insulation, sealed gasketed door 820 mm | D13: 1 of the 15 bays is the sealed server compartment | E13: lot | F13: 1 | H13: CN | J13: =IF(OR($I13="",$H13="LOCAL"),"",ROUND($F13*$I13,0))
A14: B-06 | B14: Server compartment fire-rated lining upgrade | C14: FRL 60/60/60 board system to compartment walls and ceiling | D14: Certifier acceptance path confirmed by principal | E14: lot | F14: 1 | H14: CN | J14: =IF(OR($I14="",$H14="LOCAL"),"",ROUND($F14*$I14,0))
A15: B-07 | B15: Split air-conditioner for server compartment, 2.5 kW, pre-wired | C15: RCM marked; R32; wall-mount head + external condenser bracket | E15: ea | F15: 1 | G15: 45 | H15: CN | J15: =IF(OR($I15="",$H15="LOCAL"),"",ROUND($F15*$I15,0))
A16: B-08 | B16: Inter-container junction weather seal, full height | C16: EPDM membrane + folded cover flashing | D16: 2 junctions at the rear corners | E16: run | F16: 2 | H16: CN | J16: =IF(OR($I16="",$H16="LOCAL"),"",ROUND($F16*$I16,0))
A17: B-09 | B17: Container-top edge kerb angle | C17: 75 x 75 x 6 EA G300, HDG, drilled for bearer fixings | D17: Perimeter of the 3.001 m storage deck, approx. 44 m | E17: lot | F17: 1 | G17: 300 | H17: CN | J17: =IF(OR($I17="",$H17="LOCAL"),"",ROUND($F17*$I17,0))
A18: B-10 | B18: Container door retention / latch-open hardware set | C18: Galv hold-open stays + padlockable keepers | D18: Existing container end doors retained | E18: set | F18: 6 | G18: 30 | H18: CN | J18: =IF(OR($I18="",$H18="LOCAL"),"",ROUND($F18*$I18,0))
A19: B-11 | B19: Vent blank-off and roof penetration patch | C19: Seal-welded patches, primed | E19: lot | F19: 1 | H19: CN | J19: =IF(OR($I19="",$H19="LOCAL"),"",ROUND($F19*$I19,0))
A20: B-12 | B20: In-bay cable duct and lighting channel, per bay | C20: Galv slotted duct 75 x 50 with lid, bay length | D20: Feeds bench GPO rail and bay strip light | E20: ea | F20: 15 | G20: 120 | H20: CN | J20: =IF(OR($I20="",$H20="LOCAL"),"",ROUND($F20*$I20,0))
A21: B-13 | B21: Container, bay and plant signage set | C21: Engraved traffolyte + reflective bay numbers | E21: lot | F21: 1 | H21: CN | J21: =IF(OR($I21="",$H21="LOCAL"),"",ROUND($F21*$I21,0))
A22: C | B22: PRIMARY STEEL — PORTAL FRAMES
A23: C-01 | B23: Portal column 360 UB 44.7, cut length approx. 6.90 m | C23: AS/NZS 3679.1 grade 300; fabrication AS/NZS 5131 CC2 | D23: 6 frames x 2 columns; eave height 6.896 m | E23: ea | F23: 12 | G23: 3701 | H23: CN | J23: =IF(OR($I23="",$H23="LOCAL"),"",ROUND($F23*$I23,0))
A24: C-02 | B24: Portal rafter 360 UB 44.7, cut length approx. 8.85 m | C24: AS/NZS 3679.1 grade 300; 10.0 deg pitch; span 17.420 m | D24: 6 frames x 2 rafters | E24: ea | F24: 12 | G24: 4747 | H24: CN | J24: =IF(OR($I24="",$H24="LOCAL"),"",ROUND($F24*$I24,0))
A25: C-03 | B25: Eave haunch cutting ex 360 UB 44.7, approx. 1.75 m, with web plate | C25: Profile-cut ex parent section; weld AS/NZS 1554.1 SP | D25: Haunch soffit at 6.082 m governs crane clearance — hold this dimension | E25: ea | F25: 12 | G25: 900 | H25: CN | J25: =IF(OR($I25="",$H25="LOCAL"),"",ROUND($F25*$I25,0))
A26: C-04 | B26: Apex haunch / connection plate pair | C26: 20 mm plate grade 350, match-drilled | E26: set | F26: 6 | G26: 240 | H26: CN | J26: =IF(OR($I26="",$H26="LOCAL"),"",ROUND($F26*$I26,0))
A27: C-05 | B27: Column base plate 350 x 350 x 25 with stiffeners | C27: Grade 250 plate, shop-welded to column | E27: ea | F27: 12 | G27: 660 | H27: CN | J27: =IF(OR($I27="",$H27="LOCAL"),"",ROUND($F27*$I27,0))
A28: C-06 | B28: Gable / end-wall post 250 UB 25.7, lengths 6.0 - 8.4 m | C28: AS/NZS 3679.1 grade 300 | D28: Front and rear gables; supports girts and door framing | E28: ea | F28: 6 | G28: 1080 | H28: CN | J28: =IF(OR($I28="",$H28="LOCAL"),"",ROUND($F28*$I28,0))
A29: C-07 | B29: Roller-door portal: jamb posts + head beam ex 250 UB | C29: Head gives 2.875 m clear above the 4.0 x 4.0 m opening | E29: set | F29: 1 | G29: 400 | H29: CN | J29: =IF(OR($I29="",$H29="LOCAL"),"",ROUND($F29*$I29,0))
A30: C-08 | B30: Holding-down bolt assembly M24 grade 4.6 HDG, cast-in, with template | C30: AS/NZS 4680 galv; 4 bolts per column + ply setting template | D30: Templates ship first if requested — pits and slab are local works | E30: set | F30: 12 | G30: 120 | H30: CN | J30: =IF(OR($I30="",$H30="LOCAL"),"",ROUND($F30*$I30,0))
A31: C-09 | B31: Structural bolt sets M20/M24 PC 8.8 HDG | C31: AS/NZS 1252 assemblies, batch-certified | D31: All frame, splice and bracket connections | E31: lot | F31: 1 | G31: 350 | H31: CN | J31: =IF(OR($I31="",$H31="LOCAL"),"",ROUND($F31*$I31,0))
A32: C-10 | B32: Purlin, girt, fly-brace and bracket cleats, shop-welded | C32: Grade 250/300 fittings | E32: lot | F32: 1 | G32: 450 | H32: CN | J32: =IF(OR($I32="",$H32="LOCAL"),"",ROUND($F32*$I32,0))
A33: C-11 | B33: Fabrication allowance: connection plates, stiffeners, shims | C33: Grade 250/300 | D33: Balancing allowance within the 20.7 t scheduled steel | E33: lot | F33: 1 | G33: 240 | H33: CN | J33: =IF(OR($I33="",$H33="LOCAL"),"",ROUND($F33*$I33,0))
A34: C-12 | B34: Surface protection, all group C-F steel | C34: Abrasive blast Sa2.5; HDG AS/NZS 4680, or duplex HDG + PU topcoat where noted | D34: Quote as rate per tonne; mass carried on member lines | E34: lot | F34: 1 | H34: CN | J34: =IF(OR($I34="",$H34="LOCAL"),"",ROUND($F34*$I34,0))
A35: D | B35: SECONDARY STEEL — PURLINS, GIRTS, CANOPIES
A36: D-01 | B36: Roof purlin Z200-19, punched, with laps | C36: AS 1397 G450 Z350; AS/NZS 4600 design | D36: 15 purlin lines front to back; 219.5 m net + laps | E36: m | F36: 242 | G36: 1375 | H36: CN | J36: =IF(OR($I36="",$H36="LOCAL"),"",ROUND($F36*$I36,0))
A37: D-02 | B37: Wall girt Z200-15, punched | C37: AS 1397 G450 Z350 | D37: Side walls and both gables | E37: m | F37: 240 | G37: 1070 | H37: CN | J37: =IF(OR($I37="",$H37="LOCAL"),"",ROUND($F37*$I37,0))
A38: D-03 | B38: Eave strut C200-19 | C38: AS 1397 G450 Z350 | D38: Both eaves, 14.63 m each | E38: m | F38: 29.3 | G38: 166 | H38: CN | J38: =IF(OR($I38="",$H38="LOCAL"),"",ROUND($F38*$I38,0))
A39: D-04 | B39: Ridge purlin pair + ridge ties | C39: Z200-19 + tie straps | E39: lot | F39: 1 | G39: 120 | H39: CN | J39: =IF(OR($I39="",$H39="LOCAL"),"",ROUND($F39*$I39,0))
A40: D-05 | B40: Roof purlin bridging rows | C40: Proprietary bridging, 3 rows per slope | E40: lot | F40: 1 | G40: 180 | H40: CN | J40: =IF(OR($I40="",$H40="LOCAL"),"",ROUND($F40*$I40,0))
...

Sheet Group summary
A1: GROUP SUMMARY — quote rollup
A3: Group | B3: Title | C3: Items | D3: Mass (kg) | E3: Base CN (USD) | F3: Options (USD) | G3: Local (excl.)
A4: A | B4: ISO containers & inter-connection | C4: =COUNTIFS(BOM!$A$2:$A$270,"A-*") -> 5 | D4: =SUMIFS(BOM!$G$2:$G$270,BOM!$A$2:$A$270,"A-*") -> 11916 | E4: =SUMIFS(BOM!$J$2:$J$270,BOM!$A$2:$A$270,"A-*",BOM!$H$2:$H$270,"CN") -> 0 | F4: =SUMIFS(BOM!$J$2:$J$270,BOM!$A$2:$A$270,"A-*",BOM!$H$2:$H$270,"CN-OPT") -> 0 | G4: =IF(COUNTIFS(BOM!$A$2:$A$270,"A-*",BOM!$H$2:$H$270,"LOCAL")>0,"local items","")
A5: B | B5: Container modification & bay structure | C5: =COUNTIFS(BOM!$A$2:$A$270,"B-*") -> 13 | D5: =SUMIFS(BOM!$G$2:$G$270,BOM!$A$2:$A$270,"B-*") -> 2835 | E5: =SUMIFS(BOM!$J$2:$J$270,BOM!$A$2:$A$270,"B-*",BOM!$H$2:$H$270,"CN") -> 0 | F5: =SUMIFS(BOM!$J$2:$J$270,BOM!$A$2:$A$270,"B-*",BOM!$H$2:$H$270,"CN-OPT") -> 0 | G5: =IF(COUNTIFS(BOM!$A$2:$A$270,"B-*",BOM!$H$2:$H$270,"LOCAL")>0,"local items","")
A6: C | B6: Primary steel — portal frames | C6: =COUNTIFS(BOM!$A$2:$A$270,"C-*") -> 12 | D6: =SUMIFS(BOM!$G$2:$G$270,BOM!$A$2:$A$270,"C-*") -> 12888 | E6: =SUMIFS(BOM!$J$2:$J$270,BOM!$A$2:$A$270,"C-*",BOM!$H$2:$H$270,"CN") -> 0 | F6: =SUMIFS(BOM!$J$2:$J$270,BOM!$A$2:$A$270,"C-*",BOM!$H$2:$H$270,"CN-OPT") -> 0 | G6: =IF(COUNTIFS(BOM!$A$2:$A$270,"C-*",BOM!$H$2:$H$270,"LOCAL")>0,"local items","")
A7: D | B7: Secondary steel — purlins, girts, canopies | C7: =COUNTIFS(BOM!$A$2:$A$270,"D-*") -> 11 | D7: =SUMIFS(BOM!$G$2:$G$270,BOM!$A$2:$A$270,"D-*") -> 3691 | E7: =SUMIFS(BOM!$J$2:$J$270,BOM!$A$2:$A$270,"D-*",BOM!$H$2:$H$270,"CN") -> 0 | F7: =SUMIFS(BOM!$J$2:$J$270,BOM!$A$2:$A$270,"D-*",BOM!$H$2:$H$270,"CN-OPT") -> 0 | G7: =IF(COUNTIFS(BOM!$A$2:$A$270,"D-*",BOM!$H$2:$H$270,"LOCAL")>0,"local items","")
A8: E | B8: Bracing | C8: =COUNTIFS(BOM!$A$2:$A$270,"E-*") -> 6 | D8: =SUMIFS(BOM!$G$2:$G$270,BOM!$A$2:$A$270,"E-*") -> 1545 | E8: =SUMIFS(BOM!$J$2:$J$270,BOM!$A$2:$A$270,"E-*",BOM!$H$2:$H$270,"CN") -> 0 | F8: =SUMIFS(BOM!$J$2:$J$270,BOM!$A$2:$A$270,"E-*",BOM!$H$2:$H$270,"CN-OPT") -> 0 | G8: =IF(COUNTIFS(BOM!$A$2:$A$270,"E-*",BOM!$H$2:$H$270,"LOCAL")>0,"local items","")
A9: F | B9: Crane runway | C9: =COUNTIFS(BOM!$A$2:$A$270,"F-*") -> 8 | D9: =SUMIFS(BOM!$G$2:$G$270,BOM!$A$2:$A$270,"F-*") -> 2576 | E9: =SUMIFS(BOM!$J$2:$J$270,BOM!$A$2:$A$270,"F-*",BOM!$H$2:$H$270,"CN") -> 0 | F9: =SUMIFS(BOM!$J$2:$J$270,BOM!$A$2:$A$270,"F-*",BOM!$H$2:$H$270,"CN-OPT") -> 0 | G9: =IF(COUNTIFS(BOM!$A$2:$A$270,"F-*",BOM!$H$2:$H$270,"LOCAL")>0,"local items","")
A10: G | B10: Overhead crane, 2000 kg | C10: =COUNTIFS(BOM!$A$2:$A$270,"G-*") -> 9 | D10: =SUMIFS(BOM!$G$2:$G$270,BOM!$A$2:$A$270,"G-*") -> 3700 | E10: =SUMIFS(BOM!$J$2:$J$270,BOM!$A$2:$A$270,"G-*",BOM!$H$2:$H$270,"CN") -> 0 | F10: =SUMIFS(BOM!$J$2:$J$270,BOM!$A$2:$A$270,"G-*",BOM!$H$2:$H$270,"CN-OPT") -> 0 | G10: =IF(COUNTIFS(BOM!$A$2:$A$270,"G-*",BOM!$H$2:$H$270,"LOCAL")>0,"local items","")
A11: H | B11: Envelope — PIR panels, flashings, rainwater | C11: =COUNTIFS(BOM!$A$2:$A$270,"H-*") -> 13 | D11: =SUMIFS(BOM!$G$2:$G$270,BOM!$A$2:$A$270,"H-*") -> 8460 | E11: =SUMIFS(BOM!$J$2:$J$270,BOM!$A$2:$A$270,"H-*",BOM!$H$2:$H$270,"CN") -> 0 | F11: =SUMIFS(BOM!$J$2:$J$270,BOM!$A$2:$A$270,"H-*",BOM!$H$2:$H$270,"CN-OPT") -> 0 | G11: =IF(COUNTIFS(BOM!$A$2:$A$270,"H-*",BOM!$H$2:$H$270,"LOCAL")>0,"local items","")
A12: I | B12: Doors | C12: =COUNTIFS(BOM!$A$2:$A$270,"I-*") -> 8 | D12: =SUMIFS(BOM!$G$2:$G$270,BOM!$A$2:$A$270,"I-*") -> 1219 | E12: =SUMIFS(BOM!$J$2:$J$270,BOM!$A$2:$A$270,"I-*",BOM!$H$2:$H$270,"CN") -> 0 | F12: =SUMIFS(BOM!$J$2:$J$270,BOM!$A$2:$A$270,"I-*",BOM!$H$2:$H$270,"CN-OPT") -> 0 | G12: =IF(COUNTIFS(BOM!$A$2:$A$270,"I-*",BOM!$H$2:$H$270,"LOCAL")>0,"local items","")
A13: J | B13: Container-top storage deck & racking | C13: =COUNTIFS(BOM!$A$2:$A$270,"J-*") -> 10 | D13: =SUMIFS(BOM!$G$2:$G$270,BOM!$A$2:$A$270,"J-*") -> 3821 | E13: =SUMIFS(BOM!$J$2:$J$270,BOM!$A$2:$A$270,"J-*",BOM!$H$2:$H$270,"CN") -> 0 | F13: =SUMIFS(BOM!$J$2:$J$270,BOM!$A$2:$A$270,"J-*",BOM!$H$2:$H$270,"CN-OPT") -> 0 | G13: =IF(COUNTIFS(BOM!$A$2:$A$270,"J-*",BOM!$H$2:$H$270,"LOCAL")>0,"local items","")
A14: K | B14: Stair, walkway edge protection | C14: =COUNTIFS(BOM!$A$2:$A$270,"K-*") -> 8 | D14: =SUMIFS(BOM!$G$2:$G$270,BOM!$A$2:$A$270,"K-*") -> 805 | E14: =SUMIFS(BOM!$J$2:$J$270,BOM!$A$2:$A$270,"K-*",BOM!$H$2:$H$270,"CN") -> 0 | F14: =SUMIFS(BOM!$J$2:$J$270,BOM!$A$2:$A$270,"K-*",BOM!$H$2:$H$270,"CN-OPT") -> 0 | G14: =IF(COUNTIFS(BOM!$A$2:$A$270,"K-*",BOM!$H$2:$H$270,"LOCAL")>0,"local items","")
A15: L | B15: In-ground vehicle lifts, 4 x 6 t | C15: =COUNTIFS(BOM!$A$2:$A$270,"L-*") -> 10 | D15: =SUMIFS(BOM!$G$2:$G$270,BOM!$A$2:$A$270,"L-*") -> 5084 | E15: =SUMIFS(BOM!$J$2:$J$270,BOM!$A$2:$A$270,"L-*",BOM!$H$2:$H$270,"CN") -> 0 | F15: =SUMIFS(BOM!$J$2:$J$270,BOM!$A$2:$A$270,"L-*",BOM!$H$2:$H$270,"CN-OPT") -> 0 | G15: =IF(COUNTIFS(BOM!$A$2:$A$270,"L-*",BOM!$H$2:$H$270,"LOCAL")>0,"local items","")
A16: M | B16: Hydraulic power unit & reticulation | C16: =COUNTIFS(BOM!$A$2:$A$270,"M-*") -> 11 | D16: =SUMIFS(BOM!$G$2:$G$270,BOM!$A$2:$A$270,"M-*") -> 1040 | E16: =SUMIFS(BOM!$J$2:$J$270,BOM!$A$2:$A$270,"M-*",BOM!$H$2:$H$270,"CN") -> 0 | F16: =SUMIFS(BOM!$J$2:$J$270,BOM!$A$2:$A$270,"M-*",BOM!$H$2:$H$270,"CN-OPT") -> 0 | G16: =IF(COUNTIFS(BOM!$A$2:$A$270,"M-*",BOM!$H$2:$H$270,"LOCAL")>0,"local items","") -> local items
A17: N | B17: Plant sump fit-out | C17: =COUNTIFS(BOM!$A$2:$A$270,"N-*") -> 9 | D17: =SUMIFS(BOM!$G$2:$G$270,BOM!$A$2:$A$270,"N-*") -> 1883 | E17: =SUMIFS(BOM!$J$2:$J$270,BOM!$A$2:$A$270,"N-*",BOM!$H$2:$H$270,"CN") -> 0 | F17: =SUMIFS(BOM!$J$2:$J$270,BOM!$A$2:$A$270,"N-*",BOM!$H$2:$H$270,"CN-OPT") -> 0 | G17: =IF(COUNTIFS(BOM!$A$2:$A$270,"N-*",BOM!$H$2:$H$270,"LOCAL")>0,"local items","")
A18: O | B18: Floor drainage interfaces | C18: =COUNTIFS(BOM!$A$2:$A$270,"O-*") -> 5 | D18: =SUMIFS(BOM!$G$2:$G$270,BOM!$A$2:$A$270,"O-*") -> 760 | E18: =SUMIFS(BOM!$J$2:$J$270,BOM!$A$2:$A$270,"O-*",BOM!$H$2:$H$270,"CN") -> 0 | F18: =SUMIFS(BOM!$J$2:$J$270,BOM!$A$2:$A$270,"O-*",BOM!$H$2:$H$270,"CN-OPT") -> 0 | G18: =IF(COUNTIFS(BOM!$A$2:$A$270,"O-*",BOM!$H$2:$H$270,"LOCAL")>0,"local items","") -> local items
A19: P | B19: Solar array, 52.08 kW | C19: =COUNTIFS(BOM!$A$2:$A$270,"P-*") -> 11 | D19: =SUMIFS(BOM!$G$2:$G$270,BOM!$A$2:$A$270,"P-*") -> 3678 | E19: =SUMIFS(BOM!$J$2:$J$270,BOM!$A$2:$A$270,"P-*",BOM!$H$2:$H$270,"CN") -> 0 | F19: =SUMIFS(BOM!$J$2:$J$270,BOM!$A$2:$A$270,"P-*",BOM!$H$2:$H$270,"CN-OPT") -> 0 | G19: =IF(COUNTIFS(BOM!$A$2:$A$270,"P-*",BOM!$H$2:$H$270,"LOCAL")>0,"local items","")
A20: Q | B20: Inverters, battery storage, EV charging | C20: =COUNTIFS(BOM!$A$2:$A$270,"Q-*") -> 9 | D20: =SUMIFS(BOM!$G$2:$G$270,BOM!$A$2:$A$270,"Q-*") -> 1364 | E20: =SUMIFS(BOM!$J$2:$J$270,BOM!$A$2:$A$270,"Q-*",BOM!$H$2:$H$270,"CN") -> 0 | F20: =SUMIFS(BOM!$J$2:$J$270,BOM!$A$2:$A$270,"Q-*",BOM!$H$2:$H$270,"CN-OPT") -> 0 | G20: =IF(COUNTIFS(BOM!$A$2:$A$270,"Q-*",BOM!$H$2:$H$270,"LOCAL")>0,"local items","")
A21: R | B21: Plant lean-to, 3.0 x 6.0 m | C21: =COUNTIFS(BOM!$A$2:$A$270,"R-*") -> 7 | D21: =SUMIFS(BOM!$G$2:$G$270,BOM!$A$2:$A$270,"R-*") -> 1685 | E21: =SUMIFS(BOM!$J$2:$J$270,BOM!$A$2:$A$270,"R-*",BOM!$H$2:$H$270,"CN") -> 0 | F21: =SUMIFS(BOM!$J$2:$J$270,BOM!$A$2:$A$270,"R-*",BOM!$H$2:$H$270,"CN-OPT") -> 0 | G21: =IF(COUNTIFS(BOM!$A$2:$A$270,"R-*",BOM!$H$2:$H$270,"LOCAL")>0,"local items","")
A22: S | B22: Main electrical distribution | C22: =COUNTIFS(BOM!$A$2:$A$270,"S-*") -> 13 | D22: =SUMIFS(BOM!$G$2:$G$270,BOM!$A$2:$A$270,"S-*") -> 1432 | E22: =SUMIFS(BOM!$J$2:$J$270,BOM!$A$2:$A$270,"S-*",BOM!$H$2:$H$270,"CN") -> 0 | F22: =SUMIFS(BOM!$J$2:$J$270,BOM!$A$2:$A$270,"S-*",BOM!$H$2:$H$270,"CN-OPT") -> 0 | G22: =IF(COUNTIFS(BOM!$A$2:$A$270,"S-*",BOM!$H$2:$H$270,"LOCAL")>0,"local items","")
A23: T | B23: Lighting | C23: =COUNTIFS(BOM!$A$2:$A$270,"T-*") -> 9 | D23: =SUMIFS(BOM!$G$2:$G$270,BOM!$A$2:$A$270,"T-*") -> 166 | E23: =SUMIFS(BOM!$J$2:$J$270,BOM!$A$2:$A$270,"T-*",BOM!$H$2:$H$270,"CN") -> 0 | F23: =SUMIFS(BOM!$J$2:$J$270,BOM!$A$2:$A$270,"T-*",BOM!$H$2:$H$270,"CN-OPT") -> 0 | G23: =IF(COUNTIFS(BOM!$A$2:$A$270,"T-*",BOM!$H$2:$H$270,"LOCAL")>0,"local items","")
A24: U | B24: Sensors, control, security, network | C24: =COUNTIFS(BOM!$A$2:$A$270,"U-*") -> 23 | D24: =SUMIFS(BOM!$G$2:$G$270,BOM!$A$2:$A$270,"U-*") -> 121 | E24: =SUMIFS(BOM!$J$2:$J$270,BOM!$A$2:$A$270,"U-*",BOM!$H$2:$H$270,"CN") -> 0 | F24: =SUMIFS(BOM!$J$2:$J$270,BOM!$A$2:$A$270,"U-*",BOM!$H$2:$H$270,"CN-OPT") -> 0 | G24: =IF(COUNTIFS(BOM!$A$2:$A$270,"U-*",BOM!$H$2:$H$270,"LOCAL")>0,"local items","")
A25: V | B25: Service reels & workshop services | C25: =COUNTIFS(BOM!$A$2:$A$270,"V-*") -> 8 | D25: =SUMIFS(BOM!$G$2:$G$270,BOM!$A$2:$A$270,"V-*") -> 630 | E25: =SUMIFS(BOM!$J$2:$J$270,BOM!$A$2:$A$270,"V-*",BOM!$H$2:$H$270,"CN") -> 0 | F25: =SUMIFS(BOM!$J$2:$J$270,BOM!$A$2:$A$270,"V-*",BOM!$H$2:$H$270,"CN-OPT") -> 0 | G25: =IF(COUNTIFS(BOM!$A$2:$A$270,"V-*",BOM!$H$2:$H$270,"LOCAL")>0,"local items","")
A26: W | B26: Workbenches & bay fit-out | C26: =COUNTIFS(BOM!$A$2:$A$270,"W-*") -> 5 | D26: =SUMIFS(BOM!$G$2:$G$270,BOM!$A$2:$A$270,"W-*") -> 2315 | E26: =SUMIFS(BOM!$J$2:$J$270,BOM!$A$2:$A$270,"W-*",BOM!$H$2:$H$270,"CN") -> 0 | F26: =SUMIFS(BOM!$J$2:$J$270,BOM!$A$2:$A$270,"W-*",BOM!$H$2:$H$270,"CN-OPT") -> 0 | G26: =IF(COUNTIFS(BOM!$A$2:$A$270,"W-*",BOM!$H$2:$H$270,"LOCAL")>0,"local items","")
A27: X | B27: Fixings, sealants, consumables, export packing | C27: =COUNTIFS(BOM!$A$2:$A$270,"X-*") -> 9 | D27: =SUMIFS(BOM!$G$2:$G$270,BOM!$A$2:$A$270,"X-*") -> 825 | E27: =SUMIFS(BOM!$J$2:$J$270,BOM!$A$2:$A$270,"X-*",BOM!$H$2:$H$270,"CN") -> 0 | F27: =SUMIFS(BOM!$J$2:$J$270,BOM!$A$2:$A$270,"X-*",BOM!$H$2:$H$270,"CN-OPT") -> 0 | G27: =IF(COUNTIFS(BOM!$A$2:$A$270,"X-*",BOM!$H$2:$H$270,"LOCAL")>0,"local items","")
A28: Y | B28: Local supply & site works (info only — excluded from this RFQ) | C28: =COUNTIFS(BOM!$A$2:$A$270,"Y-*") -> 12 | D28: =SUMIFS(BOM!$G$2:$G$270,BOM!$A$2:$A$270,"Y-*") -> 0 | E28: =SUMIFS(BOM!$J$2:$J$270,BOM!$A$2:$A$270,"Y-*",BOM!$H$2:$H$270,"CN") -> 0 | F28: =SUMIFS(BOM!$J$2:$J$270,BOM!$A$2:$A$270,"Y-*",BOM!$H$2:$H$270,"CN-OPT") -> 0 | G28: =IF(COUNTIFS(BOM!$A$2:$A$270,"Y-*",BOM!$H$2:$H$270,"LOCAL")>0,"local items","") -> local items
B29: TOTAL | C29: =SUM(C4:C28) -> 244 | D29: =SUM(D4:D28) -> 74439 | E29: =SUM(E4:E28) -> 0 | F29: =SUM(F4:F28) -> 0
B32: COMMERCIAL SUMMARY (tenderer completes yellow cells)
B33: Subtotal — base scope, ex-works packed | E33: =E29 -> 0
B34: Inland haulage + export formalities, FOB nominated port
B35: Sea freight, 3 SOC containers + additional units, to Port of Brisbane
B36: Marine insurance (110% CIF value)
B37: Third-party pre-shipment inspection allowance
B38: TOTAL — CIF Brisbane, base scope | E38: =SUM(E33:E37) -> 0
B39: Priced options total (info) | E39: =F29 -> 0
B41: Rates are FOB-basis unit prices in USD. State the nominated loading port with your offer. DDP options may be offered separately. Nominal masses are for freight planning only — final masses come from shop detailing.

Sheet Sensor schedule
A1: SENSOR & CONTROL POINT SCHEDULE — 61 points, 15 types
A2: Everything runs on sensors — there are no wall switches. Open protocols: MQTT + Modbus TCP, integrating with an existing Home Assistant installation.
A4: Ref | B4: Sensor type | C4: Points | D4: BOM ref | E4: Notes
A5: S1 | B5: mmWave presence, internal | C5: 8 | D5: U-03
A6: S2 | B6: PIR motion, external | C6: 6 | D6: U-04
A7: S3 | B7: Lux | C7: 4 | D7: U-05
A8: S4 | B8: Temperature / humidity | C8: 6 | D8: U-06
A9: S5 | B9: CO (vehicle exhaust) | C9: 3 | D9: U-07
A10: S6 | B10: CO2 | C10: 3 | D10: U-08
A11: S7 | B11: Smoke / heat, interlinked | C11: 6 | D11: U-09
A12: S8 | B12: Door / gate contact | C12: 11 | D12: U-10
A13: S9 | B13: Roller-door position encoder | C13: 1 | D13: U-11
A14: S10 | B14: Water leak probe | C14: 3 | D14: U-12
A15: S11 | B15: Oil-in-water (sump interlock) | C15: 1 | D15: N-05
A16: S12 | B16: Sump high-level float | C16: 1 | D16: N-07
... A19: S15 | B19: Vibration / tamper | C19: 1 | D19: U-15
B20: TOTAL SENSOR POINTS | C20: =SUM(C5:C19) -> 61
B22: CCTV cameras | C22: 9 (6 external + 3 internal)
B23: Credential readers (no keypads) | C23: 4
B24: External luminaires, sensor-driven | C24: 10
B26: Five functions are deliberately NOT sensor-only (life-safety): emergency lighting, switchboard isolation, a manual lighting override, hold-to-run on the crane and lifts, and mechanical egress on every door.

Sheet Dimensions
A1: SCHEDULE OF PRINCIPAL DIMENSIONS — rev C, 2026-08-24
A2: Every number is computed from one parameter file — the model, this schedule and the BOM cannot disagree. Status: for engineering. NOT a certified design.
A4: Element | B4: Value | C4: Note
A5: Clear workshop bay | B5: 12.192 x 12.192 m | C5: containers meet at both rear corners
A6: Building envelope | B6: 17.068 x 14.630 m | C6: footprint 249.7 m2
A7: Eave / ridge | B7: 6.896 / 8.432 m | C7: 10.0 deg pitch, equal both slopes
A8: Portal frames | B8: 6 at 2.960 m | C8: 17.420 m span, 360 UB 44.7, haunched
A9: Envelope | B9: 100 mm PIR | C9: 607 m2 roof, wall and gable
A10: Roller door | B10: 4.0 x 4.0 m | C10: 2.875 m clear above the head beam
A11: Overhead crane | B11: 2000 kg, 17.420 m span | C11: hook 5.154 m; reaches 1.914 m over each container top
A12: Vehicle lift | B12: 4 x 6 t, 3.0 m stroke | C12: flush pads on a 4.0 x 3.5 m grid, removable cross beams
A13: Hydraulic plant | B13: 15 kW in a floor sump | C13: 2.4 x 1.6 x 1.8 m, bunded, flush covered
A14: Container storage deck | B14: 3.001 m level | C14: max craned item 1.903 m tall
A15: Container bays | B15: 15 openings at 2.288 m | C15: 13 workbenches + sealed server compartment
... A21: Connected load | B21: 84.9 kW | C21: against a 71.9 kVA supply — load management required
A23: Site wind region, terrain category and soil classification are not yet confirmed. Wind-rated items (envelope, roller door, PV mounting, structure) are quoted against the stated sections; re-pricing after site data lands is handled via the per-tonne and per-m2 rates in this workbook.
